Workbook
Name boosted: 'BOP - T'!$N$17:$O$17
Name calendar: Start!$AI$5:$AS$18
Name chassisShortStatsNew: Stats!$BK$5:$BM$8
Name chassisStatsBalanced: 'BOP - T'!$AZ$5:$BF$7
Name chassisStatsNew: Stats!$BB$5:$BH$8
Name driverStats: Drivers!$B$5:$E$91
Name engineStatsBalanced: 'BOP - T'!$AZ$5:$BF$8
Name engineStatsNew: Stats!$BP$5:$BT$8
Name lengthDetails: Start!$AN$21:$AP$24
Name pointsSystem: Start!$BZ$5:$CC$42
Name pointsSystem2: Start!$CF$5:$CH$42
Name trackList: Start!$BI$5:$BS$41
Name tyreStatsNew: Stats!$BW$5:$BY$7

Sheet tyre wear sim
B2: venue | C2: 2
B3: team | C3: 3 | E3: bruh | G3: min perf | H3: =C8 - 50 -> 48
B4: spine | C4: 2 | E4: march | G4: max perf | H4: =C8 - 35 -> 63
B5: tyres | C5: 2 | E5: pirelli
B6: drivers | C6: 2
B7: race len | C7: 28
B8: tyre perf | C8: 98 | E8: div | F8: 4
B10: lap no | D10: perf | E10: drop off | F10: rem life | G10: max life | I10: max - rem | J10: div 10 flr | K10: (deg flr +1) / 2 | L10: flr | N10: range min | O10: range max | Q10: /1 | R10: /1.5 | S10: /2 | T10: /3 | U10: /4
B12: lap 1 | D12: =100 - E12 -> 100 | E12: =FLOOR((G12 - F12) / 10, 1) * K12 -> 0 | F12: =G12 - FLOOR(RANDBETWEEN(N12, O12) / F8, 1) -> 97 | G12: 100 | I12: =G12 - E12 -> 100 | J12: =FLOOR(I12 / 10, 1) -> 10 | K12: =C6 -> 2 | L12: =J12 * K12 -> 20 | N12: =SUM(C2:C6) -> 11 | O12: =N12 + (3 * C6) -> 17 | Q12: =FLOOR(RANDBETWEEN(N12, O12), 1) -> 15 | R12: =FLOOR(RANDBETWEEN(N12, O12) / 1.5, 1) -> 9 | S12: =FLOOR(RANDBETWEEN(N12, O12) / 2, 1) -> 5 | T12: =FLOOR(RANDBETWEEN(N12, O12) / 3, 1) -> 5 | U12: =FLOOR(RANDBETWEEN(N12, O12) / 4, 1) -> 2
B13: lap 2 | D13: =100 - E13 -> 100 | E13: =FLOOR((G13 - F13) / 10, 1) * K13 -> 0 | F13: =F12 - FLOOR(RANDBETWEEN(N13, O13) / F8, 1) -> 94 | G13: =G12 -> 100 | I13: =G13 - E13 -> 100 | J13: =FLOOR(I13 / 10, 1) -> 10 | K13: =C6 -> 2 | L13: =J13 * K13 -> 20 | N13: =N12 -> 11 | O13: =O12 -> 17 | Q13: =FLOOR(RANDBETWEEN(N13, O13), 1) -> 12 | R13: =FLOOR(RANDBETWEEN(N13, O13) / 1.5, 1) -> 8 | S13: =FLOOR(RANDBETWEEN(N13, O13) / 2, 1) -> 8 | T13: =FLOOR(RANDBETWEEN(N13, O13) / 3, 1) -> 5 | U13: =FLOOR(RANDBETWEEN(N13, O13) / 4, 1) -> 3
B14: lap 3 | D14: =100 - E14 -> 100 | E14: =FLOOR((G14 - F14) / 10, 1) * K14 -> 0 | F14: =F13 - FLOOR(RANDBETWEEN(N14, O14) / F8, 1) -> 91 | G14: =G13 -> 100 | I14: =G14 - E14 -> 100 | J14: =FLOOR(I14 / 10, 1) -> 10 | K14: =C6 -> 2 | L14: =J14 * K14 -> 20 | N14: =N13 -> 11 | O14: =O13 -> 17 | Q14: =FLOOR(RANDBETWEEN(N14, O14), 1) -> 14 | R14: =FLOOR(RANDBETWEEN(N14, O14) / 1.5, 1) -> 8 | S14: =FLOOR(RANDBETWEEN(N14, O14) / 2, 1) -> 6 | T14: =FLOOR(RANDBETWEEN(N14, O14) / 3, 1) -> 5 | U14: =FLOOR(RANDBETWEEN(N14, O14) / 4, 1) -> 4
B15: lap 4 | D15: =100 - E15 -> 98 | E15: =FLOOR((G15 - F15) / 10, 1) * K15 -> 2 | F15: =F14 - FLOOR(RANDBETWEEN(N15, O15) / F8, 1) -> 88 | G15: =G14 -> 100 | I15: =G15 - E15 -> 98 | J15: =FLOOR(I15 / 10, 1) -> 9 | K15: =C6 -> 2 | L15: =J15 * K15 -> 18 | N15: =N14 -> 11 | O15: =O14 -> 17 | Q15: =FLOOR(RANDBETWEEN(N15, O15), 1) -> 16 | R15: =FLOOR(RANDBETWEEN(N15, O15) / 1.5, 1) -> 11 | S15: =FLOOR(RANDBETWEEN(N15, O15) / 2, 1) -> 5 | T15: =FLOOR(RANDBETWEEN(N15, O15) / 3, 1) -> 5 | U15: =FLOOR(RANDBETWEEN(N15, O15) / 4, 1) -> 2
B16: lap 5 | D16: =100 - E16 -> 98 | E16: =FLOOR((G16 - F16) / 10, 1) * K16 -> 2 | F16: =F15 - FLOOR(RANDBETWEEN(N16, O16) / F8, 1) -> 85 | G16: =G15 -> 100 | I16: =G16 - E16 -> 98 | J16: =FLOOR(I16 / 10, 1) -> 9 | K16: =C6 -> 2 | L16: =J16 * K16 -> 18 | N16: =N15 -> 11 | O16: =O15 -> 17 | Q16: =FLOOR(RANDBETWEEN(N16, O16), 1) -> 11 | R16: =FLOOR(RANDBETWEEN(N16, O16) / 1.5, 1) -> 8 | S16: =FLOOR(RANDBETWEEN(N16, O16) / 2, 1) -> 7 | T16: =FLOOR(RANDBETWEEN(N16, O16) / 3, 1) -> 4 | U16: =FLOOR(RANDBETWEEN(N16, O16) / 4, 1) -> 4
B17: lap 6 | D17: =100 - E17 -> 98 | E17: =FLOOR((G17 - F17) / 10, 1) * K17 -> 2 | F17: =F16 - FLOOR(RANDBETWEEN(N17, O17) / F8, 1) -> 82 | G17: =G16 -> 100 | I17: =G17 - E17 -> 98 | J17: =FLOOR(I17 / 10, 1) -> 9 | K17: =C6 -> 2 | L17: =J17 * K17 -> 18 | N17: =N16 -> 11 | O17: =O16 -> 17 | Q17: =FLOOR(RANDBETWEEN(N17, O17), 1) -> 14 | R17: =FLOOR(RANDBETWEEN(N17, O17) / 1.5, 1) -> 7 | S17: =FLOOR(RANDBETWEEN(N17, O17) / 2, 1) -> 8 | T17: =FLOOR(RANDBETWEEN(N17, O17) / 3, 1) -> 5 | U17: =FLOOR(RANDBETWEEN(N17, O17) / 4, 1) -> 4
B18: lap 7 | D18: =100 - E18 -> 96 | E18: =FLOOR((G18 - F18) / 10, 1) * K18 -> 4 | F18: =F17 - FLOOR(RANDBETWEEN(N18, O18) / F8, 1) -> 79 | G18: =G17 -> 100 | I18: =G18 - E18 -> 96 | J18: =FLOOR(I18 / 10, 1) -> 9 | K18: =C6 -> 2 | L18: =J18 * K18 -> 18 | N18: =N17 -> 11 | O18: =O17 -> 17 | Q18: =FLOOR(RANDBETWEEN(N18, O18), 1) -> 16 | R18: =FLOOR(RANDBETWEEN(N18, O18) / 1.5, 1) -> 8 | S18: =FLOOR(RANDBETWEEN(N18, O18) / 2, 1) -> 5 | T18: =FLOOR(RANDBETWEEN(N18, O18) / 3, 1) -> 4 | U18: =FLOOR(RANDBETWEEN(N18, O18) / 4, 1) -> 3
B19: lap 8 | D19: =100 - E19 -> 96 | E19: =FLOOR((G19 - F19) / 10, 1) * K19 -> 4 | F19: =F18 - FLOOR(RANDBETWEEN(N19, O19) / F8, 1) -> 75 | G19: =G18 -> 100 | I19: =G19 - E19 -> 96 | J19: =FLOOR(I19 / 10, 1) -> 9 | K19: =C6 -> 2 | L19: =J19 * K19 -> 18 | N19: =N18 -> 11 | O19: =O18 -> 17 | Q19: =FLOOR(RANDBETWEEN(N19, O19), 1) -> 14 | R19: =FLOOR(RANDBETWEEN(N19, O19) / 1.5, 1) -> 10 | S19: =FLOOR(RANDBETWEEN(N19, O19) / 2, 1) -> 7 | T19: =FLOOR(RANDBETWEEN(N19, O19) / 3, 1) -> 5 | U19: =FLOOR(RANDBETWEEN(N19, O19) / 4, 1) -> 3
B20: lap 9 | D20: =100 - E20 -> 96 | E20: =FLOOR((G20 - F20) / 10, 1) * K20 -> 4 | F20: =F19 - FLOOR(RANDBETWEEN(N20, O20) / F8, 1) -> 72 | G20: =G19 -> 100 | I20: =G20 - E20 -> 96 | J20: =FLOOR(I20 / 10, 1) -> 9 | K20: =C6 -> 2 | L20: =J20 * K20 -> 18 | N20: =N19 -> 11 | O20: =O19 -> 17 | Q20: =FLOOR(RANDBETWEEN(N20, O20), 1) -> 15 | R20: =FLOOR(RANDBETWEEN(N20, O20) / 1.5, 1) -> 11 | S20: =FLOOR(RANDBETWEEN(N20, O20) / 2, 1) -> 7 | T20: =FLOOR(RANDBETWEEN(N20, O20) / 3, 1) -> 3 | U20: =FLOOR(RANDBETWEEN(N20, O20) / 4, 1) -> 3
B21: lap 10 | D21: =100 - E21 -> 94 | E21: =FLOOR((G21 - F21) / 10, 1) * K21 -> 6 | F21: =F20 - FLOOR(RANDBETWEEN(N21, O21) / F8, 1) -> 70 | G21: =G20 -> 100 | I21: =G21 - E21 -> 94 | J21: =FLOOR(I21 / 10, 1) -> 9 | K21: =C6 -> 2 | L21: =J21 * K21 -> 18 | N21: =N20 -> 11 | O21: =O20 -> 17 | Q21: =FLOOR(RANDBETWEEN(N21, O21), 1) -> 16 | R21: =FLOOR(RANDBETWEEN(N21, O21) / 1.5, 1) -> 9 | S21: =FLOOR(RANDBETWEEN(N21, O21) / 2, 1) -> 7 | T21: =FLOOR(RANDBETWEEN(N21, O21) / 3, 1) -> 5 | U21: =FLOOR(RANDBETWEEN(N21, O21) / 4, 1) -> 3
B22: lap 11 | D22: =100 - E22 -> 94 | E22: =FLOOR((G22 - F22) / 10, 1) * K22 -> 6 | F22: =F21 - FLOOR(RANDBETWEEN(N22, O22) / F8, 1) -> 68 | G22: =G21 -> 100 | I22: =G22 - E22 -> 94 | J22: =FLOOR(I22 / 10, 1) -> 9 | K22: =C6 -> 2 | L22: =J22 * K22 -> 18 | N22: =N21 -> 11 | O22: =O21 -> 17 | Q22: =FLOOR(RANDBETWEEN(N22, O22), 1) -> 11 | R22: =FLOOR(RANDBETWEEN(N22, O22) / 1.5, 1) -> 8 | S22: =FLOOR(RANDBETWEEN(N22, O22) / 2, 1) -> 8 | T22: =FLOOR(RANDBETWEEN(N22, O22) / 3, 1) -> 5 | U22: =FLOOR(RANDBETWEEN(N22, O22) / 4, 1) -> 2
B23: lap 12 | D23: =100 - E23 -> 94 | E23: =FLOOR((G23 - F23) / 10, 1) * K23 -> 6 | F23: =F22 - FLOOR(RANDBETWEEN(N23, O23) / F8, 1) -> 65 | G23: =G22 -> 100 | I23: =G23 - E23 -> 94 | J23: =FLOOR(I23 / 10, 1) -> 9 | K23: =C6 -> 2 | L23: =J23 * K23 -> 18 | N23: =N22 -> 11 | O23: =O22 -> 17 | Q23: =FLOOR(RANDBETWEEN(N23, O23), 1) -> 13 | R23: =FLOOR(RANDBETWEEN(N23, O23) / 1.5, 1) -> 10 | S23: =FLOOR(RANDBETWEEN(N23, O23) / 2, 1) -> 8 | T23: =FLOOR(RANDBETWEEN(N23, O23) / 3, 1) -> 4 | U23: =FLOOR(RANDBETWEEN(N23, O23) / 4, 1) -> 3
B24: lap 13 | D24: =100 - E24 -> 94 | E24: =FLOOR((G24 - F24) / 10, 1) * K24 -> 6 | F24: =F23 - FLOOR(RANDBETWEEN(N24, O24) / F8, 1) -> 61 | G24: =G23 -> 100 | I24: =G24 - E24 -> 94 | J24: =FLOOR(I24 / 10, 1) -> 9 | K24: =C6 -> 2 | L24: =J24 * K24 -> 18 | N24: =N23 -> 11 | O24: =O23 -> 17 | Q24: =FLOOR(RANDBETWEEN(N24, O24), 1) -> 12 | R24: =FLOOR(RANDBETWEEN(N24, O24) / 1.5, 1) -> 9 | S24: =FLOOR(RANDBETWEEN(N24, O24) / 2, 1) -> 8 | T24: =FLOOR(RANDBETWEEN(N24, O24) / 3, 1) -> 4 | U24: =FLOOR(RANDBETWEEN(N24, O24) / 4, 1) -> 4
B25: lap 14 | D25: =100 - E25 -> 92 | E25: =FLOOR((G25 - F25) / 10, 1) * K25 -> 8 | F25: =F24 - FLOOR(RANDBETWEEN(N25, O25) / F8, 1) -> 58 | G25: =G24 -> 100 | I25: =G25 - E25 -> 92 | J25: =FLOOR(I25 / 10, 1) -> 9 | K25: =C6 -> 2 | L25: =J25 * K25 -> 18 | N25: =N24 -> 11 | O25: =O24 -> 17 | Q25: =FLOOR(RANDBETWEEN(N25, O25), 1) -> 11 | R25: =FLOOR(RANDBETWEEN(N25, O25) / 1.5, 1) -> 10 | S25: =FLOOR(RANDBETWEEN(N25, O25) / 2, 1) -> 6 | T25: =FLOOR(RANDBETWEEN(N25, O25) / 3, 1) -> 4 | U25: =FLOOR(RANDBETWEEN(N25, O25) / 4, 1) -> 4
B26: lap 15 | D26: =100 - E26 -> 92 | E26: =FLOOR((G26 - F26) / 10, 1) * K26 -> 8 | F26: =F25 - FLOOR(RANDBETWEEN(N26, O26) / F8, 1) -> 55 | G26: =G25 -> 100 | I26: =G26 - E26 -> 92 | J26: =FLOOR(I26 / 10, 1) -> 9 | K26: =C6 -> 2 | L26: =J26 * K26 -> 18 | N26: =N25 -> 11 | O26: =O25 -> 17 | Q26: =FLOOR(RANDBETWEEN(N26, O26), 1) -> 15 | R26: =FLOOR(RANDBETWEEN(N26, O26) / 1.5, 1) -> 11 | S26: =FLOOR(RANDBETWEEN(N26, O26) / 2, 1) -> 8 | T26: =FLOOR(RANDBETWEEN(N26, O26) / 3, 1) -> 5 | U26: =FLOOR(RANDBETWEEN(N26, O26) / 4, 1) -> 4
B27: lap 16 | D27: =100 - E27 -> 92 | E27: =FLOOR((G27 - F27) / 10, 1) * K27 -> 8 | F27: =F26 - FLOOR(RANDBETWEEN(N27, O27) / F8, 1) -> 52 | G27: =G26 -> 100 | I27: =G27 - E27 -> 92 | J27: =FLOOR(I27 / 10, 1) -> 9 | K27: =C6 -> 2 | L27: =J27 * K27 -> 18 | N27: =N26 -> 11 | O27: =O26 -> 17 | Q27: =FLOOR(RANDBETWEEN(N27, O27), 1) -> 12 | R27: =FLOOR(RANDBETWEEN(N27, O27) / 1.5, 1) -> 7 | S27: =FLOOR(RANDBETWEEN(N27, O27) / 2, 1) -> 6 | T27: =FLOOR(RANDBETWEEN(N27, O27) / 3, 1) -> 5 | U27: =FLOOR(RANDBETWEEN(N27, O27) / 4, 1) -> 2
B28: lap 17 | D28: =100 - E28 -> 90 | E28: =FLOOR((G28 - F28) / 10, 1) * K28 -> 10 | F28: =F27 - FLOOR(RANDBETWEEN(N28, O28) / F8, 1) -> 49 | G28: =G27 -> 100 | I28: =G28 - E28 -> 90 | J28: =FLOOR(I28 / 10, 1) -> 9 | K28: =C6 -> 2 | L28: =J28 * K28 -> 18 | N28: =N27 -> 11 | O28: =O27 -> 17 | Q28: =FLOOR(RANDBETWEEN(N28, O28), 1) -> 14 | R28: =FLOOR(RANDBETWEEN(N28, O28) / 1.5, 1) -> 10 | S28: =FLOOR(RANDBETWEEN(N28, O28) / 2, 1) -> 8 | T28: =FLOOR(RANDBETWEEN(N28, O28) / 3, 1) -> 3 | U28: =FLOOR(RANDBETWEEN(N28, O28) / 4, 1) -> 4
B29: lap 18 | D29: =100 - E29 -> 90 | E29: =FLOOR((G29 - F29) / 10, 1) * K29 -> 10 | F29: =F28 - FLOOR(RANDBETWEEN(N29, O29) / F8, 1) -> 46 | G29: =G28 -> 100 | I29: =G29 - E29 -> 90 | J29: =FLOOR(I29 / 10, 1) -> 9 | K29: =C6 -> 2 | L29: =J29 * K29 -> 18 | N29: =N28 -> 11 | O29: =O28 -> 17 | Q29: =FLOOR(RANDBETWEEN(N29, O29), 1) -> 14 | R29: =FLOOR(RANDBETWEEN(N29, O29) / 1.5, 1) -> 9 | S29: =FLOOR(RANDBETWEEN(N29, O29) / 2, 1) -> 7 | T29: =FLOOR(RANDBETWEEN(N29, O29) / 3, 1) -> 4 | U29: =FLOOR(RANDBETWEEN(N29, O29) / 4, 1) -> 3
B30: lap 19 | D30: =100 - E30 -> 90 | E30: =FLOOR((G30 - F30) / 10, 1) * K30 -> 10 | F30: =F29 - FLOOR(RANDBETWEEN(N30, O30) / F8, 1) -> 42 | G30: =G29 -> 100 | I30: =G30 - E30 -> 90 | J30: =FLOOR(I30 / 10, 1) -> 9 | K30: =C6 -> 2 | L30: =J30 * K30 -> 18 | N30: =N29 -> 11 | O30: =O29 -> 17 | Q30: =FLOOR(RANDBETWEEN(N30, O30), 1) -> 11 | R30: =FLOOR(RANDBETWEEN(N30, O30) / 1.5, 1) -> 10 | S30: =FLOOR(RANDBETWEEN(N30, O30) / 2, 1) -> 8 | T30: =FLOOR(RANDBETWEEN(N30, O30) / 3, 1) -> 5 | U30: =FLOOR(RANDBETWEEN(N30, O30) / 4, 1) -> 3
B31: lap 20 | D31: =100 - E31 -> 88 | E31: =FLOOR((G31 - F31) / 10, 1) * K31 -> 12 | F31: =F30 - FLOOR(RANDBETWEEN(N31, O31) / F8, 1) -> 40 | G31: =G30 -> 100 | I31: =G31 - E31 -> 88 | J31: =FLOOR(I31 / 10, 1) -> 8 | K31: =C6 -> 2 | L31: =J31 * K31 -> 16 | N31: =N30 -> 11 | O31: =O30 -> 17 | Q31: =FLOOR(RANDBETWEEN(N31, O31), 1) -> 14 | R31: =FLOOR(RANDBETWEEN(N31, O31) / 1.5, 1) -> 9 | S31: =FLOOR(RANDBETWEEN(N31, O31) / 2, 1) -> 7 | T31: =FLOOR(RANDBETWEEN(N31, O31) / 3, 1) -> 4 | U31: =FLOOR(RANDBETWEEN(N31, O31) / 4, 1) -> 3
B32: lap 21 | D32: =100 - E32 -> 88 | E32: =FLOOR((G32 - F32) / 10, 1) * K32 -> 12 | F32: =F31 - FLOOR(RANDBETWEEN(N32, O32) / F8, 1) -> 37 | G32: =G31 -> 100 | I32: =G32 - E32 -> 88 | J32: =FLOOR(I32 / 10, 1) -> 8 | K32: =C6 -> 2 | L32: =J32 * K32 -> 16 | N32: =N31 -> 11 | O32: =O31 -> 17 | Q32: =FLOOR(RANDBETWEEN(N32, O32), 1) -> 16 | R32: =FLOOR(RANDBETWEEN(N32, O32) / 1.5, 1) -> 10 | S32: =FLOOR(RANDBETWEEN(N32, O32) / 2, 1) -> 7 | T32: =FLOOR(RANDBETWEEN(N32, O32) / 3, 1) -> 3 | U32: =FLOOR(RANDBETWEEN(N32, O32) / 4, 1) -> 2
B33: lap 22 | D33: =100 - E33 -> 88 | E33: =FLOOR((G33 - F33) / 10, 1) * K33 -> 12 | F33: =F32 - FLOOR(RANDBETWEEN(N33, O33) / F8, 1) -> 35 | G33: =G32 -> 100 | I33: =G33 - E33 -> 88 | J33: =FLOOR(I33 / 10, 1) -> 8 | K33: =C6 -> 2 | L33: =J33 * K33 -> 16 | N33: =N32 -> 11 | O33: =O32 -> 17 | Q33: =FLOOR(RANDBETWEEN(N33, O33), 1) -> 16 | R33: =FLOOR(RANDBETWEEN(N33, O33) / 1.5, 1) -> 7 | S33: =FLOOR(RANDBETWEEN(N33, O33) / 2, 1) -> 7 | T33: =FLOOR(RANDBETWEEN(N33, O33) / 3, 1) -> 5 | U33: =FLOOR(RANDBETWEEN(N33, O33) / 4, 1) -> 4
B34: lap 23 | D34: =100 - E34 -> 88 | E34: =FLOOR((G34 - F34) / 10, 1) * K34 -> 12 | F34: =F33 - FLOOR(RANDBETWEEN(N34, O34) / F8, 1) -> 32 | G34: =G33 -> 100 | I34: =G34 - E34 -> 88 | J34: =FLOOR(I34 / 10, 1) -> 8 | K34: =C6 -> 2 | L34: =J34 * K34 -> 16 | N34: =N33 -> 11 | O34: =O33 -> 17 | Q34: =FLOOR(RANDBETWEEN(N34, O34), 1) -> 14 | R34: =FLOOR(RANDBETWEEN(N34, O34) / 1.5, 1) -> 11 | S34: =FLOOR(RANDBETWEEN(N34, O34) / 2, 1) -> 7 | T34: =FLOOR(RANDBETWEEN(N34, O34) / 3, 1) -> 3 | U34: =FLOOR(RANDBETWEEN(N34, O34) / 4, 1) -> 2
B35: lap 24 | D35: =100 - E35 -> 86 | E35: =FLOOR((G35 - F35) / 10, 1) * K35 -> 14 | F35: =F34 - FLOOR(RANDBETWEEN(N35, O35) / F8, 1) -> 30 | G35: =G34 -> 100 | I35: =G35 - E35 -> 86 | J35: =FLOOR(I35 / 10, 1) -> 8 | K35: =C6 -> 2 | L35: =J35 * K35 -> 16 | N35: =N34 -> 11 | O35: =O34 -> 17 | Q35: =FLOOR(RANDBETWEEN(N35, O35), 1) -> 15 | R35: =FLOOR(RANDBETWEEN(N35, O35) / 1.5, 1) -> 8 | S35: =FLOOR(RANDBETWEEN(N35, O35) / 2, 1) -> 5 | T35: =FLOOR(RANDBETWEEN(N35, O35) / 3, 1) -> 5 | U35: =FLOOR(RANDBETWEEN(N35, O35) / 4, 1) -> 3
B36: lap 25 | D36: =100 - E36 -> 86 | E36: =FLOOR((G36 - F36) / 10, 1) * K36 -> 14 | F36: =F35 - FLOOR(RANDBETWEEN(N36, O36) / F8, 1) -> 28 | G36: =G35 -> 100 | I36: =G36 - E36 -> 86 | J36: =FLOOR(I36 / 10, 1) -> 8 | K36: =C6 -> 2 | L36: =J36 * K36 -> 16 | N36: =N35 -> 11 | O36: =O35 -> 17 | Q36: =FLOOR(RANDBETWEEN(N36, O36), 1) -> 13 | R36: =FLOOR(RANDBETWEEN(N36, O36) / 1.5, 1) -> 9 | S36: =FLOOR(RANDBETWEEN(N36, O36) / 2, 1) -> 7 | T36: =FLOOR(RANDBETWEEN(N36, O36) / 3, 1) -> 3 | U36: =FLOOR(RANDBETWEEN(N36, O36) / 4, 1) -> 4
B37: lap 26 | D37: =100 - E37 -> 86 | E37: =FLOOR((G37 - F37) / 10, 1) * K37 -> 14 | F37: =F36 - FLOOR(RANDBETWEEN(N37, O37) / F8, 1) -> 24 | G37: =G36 -> 100 | I37: =G37 - E37 -> 86 | J37: =FLOOR(I37 / 10, 1) -> 8 | K37: =C6 -> 2 | L37: =J37 * K37 -> 16 | N37: =N36 -> 11 | O37: =O36 -> 17 | Q37: =FLOOR(RANDBETWEEN(N37, O37), 1) -> 16 | R37: =FLOOR(RANDBETWEEN(N37, O37) / 1.5, 1) -> 11 | S37: =FLOOR(RANDBETWEEN(N37, O37) / 2, 1) -> 6 | T37: =FLOOR(RANDBETWEEN(N37, O37) / 3, 1) -> 5 | U37: =FLOOR(RANDBETWEEN(N37, O37) / 4, 1) -> 4
B38: lap 27 | D38: =100 - E38 -> 84 | E38: =FLOOR((G38 - F38) / 10, 1) * K38 -> 16 | F38: =F37 - FLOOR(RANDBETWEEN(N38, O38) / F8, 1) -> 20 | G38: =G37 -> 100 | I38: =G38 - E38 -> 84 | J38: =FLOOR(I38 / 10, 1) -> 8 | K38: =C6 -> 2 | L38: =J38 * K38 -> 16 | N38: =N37 -> 11 | O38: =O37 -> 17 | Q38: =FLOOR(RANDBETWEEN(N38, O38), 1) -> 12 | R38: =FLOOR(RANDBETWEEN(N38, O38) / 1.5, 1) -> 8 | S38: =FLOOR(RANDBETWEEN(N38, O38) / 2, 1) -> 8 | T38: =FLOOR(RANDBETWEEN(N38, O38) / 3, 1) -> 5 | U38: =FLOOR(RANDBETWEEN(N38, O38) / 4, 1) -> 3
B39: lap 28 | D39: =100 - E39 -> 84 | E39: =FLOOR((G39 - F39) / 10, 1) * K39 -> 16 | F39: =F38 - FLOOR(RANDBETWEEN(N39, O39) / F8, 1) -> 17 | G39: =G38 -> 100 | I39: =G39 - E39 -> 84 | J39: =FLOOR(I39 / 10, 1) -> 8 | K39: =C6 -> 2 | L39: =J39 * K39 -> 16 | N39: =N38 -> 11 | O39: =O38 -> 17 | Q39: =FLOOR(RANDBETWEEN(N39, O39), 1) -> 17 | R39: =FLOOR(RANDBETWEEN(N39, O39) / 1.5, 1) -> 8 | S39: =FLOOR(RANDBETWEEN(N39, O39) / 2, 1) -> 6 | T39: =FLOOR(RANDBETWEEN(N39, O39) / 3, 1) -> 5 | U39: =FLOOR(RANDBETWEEN(N39, O39) / 4, 1) -> 2
B40: lap 29 | D40: =100 - E40 -> 84 | E40: =FLOOR((G40 - F40) / 10, 1) * K40 -> 16 | F40: =F39 - FLOOR(RANDBETWEEN(N40, O40) / F8, 1) -> 13 | G40: =G39 -> 100 | I40: =G40 - E40 -> 84 | J40: =FLOOR(I40 / 10, 1) -> 8 | K40: =C6 -> 2 | L40: =J40 * K40 -> 16 | N40: =N39 -> 11 | O40: =O39 -> 17 | Q40: =FLOOR(RANDBETWEEN(N40, O40), 1) -> 11 | R40: =FLOOR(RANDBETWEEN(N40, O40) / 1.5, 1) -> 8 | S40: =FLOOR(RANDBETWEEN(N40, O40) / 2, 1) -> 7 | T40: =FLOOR(RANDBETWEEN(N40, O40) / 3, 1) -> 4 | U40: =FLOOR(RANDBETWEEN(N40, O40) / 4, 1) -> 3
B41: lap 30 | D41: =100 - E41 -> 82 | E41: =FLOOR((G41 - F41) / 10, 1) * K41 -> 18 | F41: =F40 - FLOOR(RANDBETWEEN(N41, O41) / F8, 1) -> 10 | G41: =G40 -> 100 | I41: =G41 - E41 -> 82 | J41: =FLOOR(I41 / 10, 1) -> 8 | K41: =C6 -> 2 | L41: =J41 * K41 -> 16 | N41: =N40 -> 11 | O41: =O40 -> 17 | Q41: =FLOOR(RANDBETWEEN(N41, O41), 1) -> 14 | R41: =FLOOR(RANDBETWEEN(N41, O41) / 1.5, 1) -> 10 | S41: =FLOOR(RANDBETWEEN(N41, O41) / 2, 1) -> 6 | T41: =FLOOR(RANDBETWEEN(N41, O41) / 3, 1) -> 5 | U41: =FLOOR(RANDBETWEEN(N41, O41) / 4, 1) -> 4
B42: lap 31 | D42: =100 - E42 -> 82 | E42: =FLOOR((G42 - F42) / 10, 1) * K42 -> 18 | F42: =F41 - FLOOR(RANDBETWEEN(N42, O42) / F8, 1) -> 7 | G42: =G41 -> 100 | I42: =G42 - E42 -> 82 | J42: =FLOOR(I42 / 10, 1) -> 8 | K42: =C6 -> 2 | L42: =J42 * K42 -> 16 | N42: =N41 -> 11 | O42: =O41 -> 17 | Q42: =FLOOR(RANDBETWEEN(N42, O42), 1) -> 15 | R42: =FLOOR(RANDBETWEEN(N42, O42) / 1.5, 1) -> 8 | S42: =FLOOR(RANDBETWEEN(N42, O42) / 2, 1) -> 6 | T42: =FLOOR(RANDBETWEEN(N42, O42) / 3, 1) -> 4 | U42: =FLOOR(RANDBETWEEN(N42, O42) / 4, 1) -> 2
B43: lap 32 | D43: =100 - E43 -> 82 | E43: =FLOOR((G43 - F43) / 10, 1) * K43 -> 18 | F43: =F42 - FLOOR(RANDBETWEEN(N43, O43) / F8, 1) -> 4 | G43: =G42 -> 100 | I43: =G43 - E43 -> 82 | J43: =FLOOR(I43 / 10, 1) -> 8 | K43: =C6 -> 2 | L43: =J43 * K43 -> 16 | N43: =N42 -> 11 | O43: =O42 -> 17 | Q43: =FLOOR(RANDBETWEEN(N43, O43), 1) -> 16 | R43: =FLOOR(RANDBETWEEN(N43, O43) / 1.5, 1) -> 11 | S43: =FLOOR(RANDBETWEEN(N43, O43) / 2, 1) -> 6 | T43: =FLOOR(RANDBETWEEN(N43, O43) / 3, 1) -> 4 | U43: =FLOOR(RANDBETWEEN(N43, O43) / 4, 1) -> 3

Sheet Start
B2: TDS12 | T2: TDS | Z2: TDS | AE2: Junior Series Points System | AI2: TDS13 | AV2: TDS13 | BI2: TDS12 | BV2: Main Series Round Format | BZ2: Whatever I call this | CF2: TDS12
B3: Team Entries | T3: Points System | Z3: Points System | AI3: Season Calendar | AV3: Season Calendar but longer | BI3: Track List | BZ3: Points System | CF3: Points System
B4: Team Name | C4: Spine | D4: Engine | E4: Tyres | I4: Spine | J4: Engine | K4: Tyres | N4: Pos | O4: Q | P4: R1 | Q4: R2 | T4: Pos | U4: Q | V4: R1 | W4: R2 | Z4: Pos | AA4: R1 | AB4: R2 | AE4: Pos | AF4: Pts | AI4: Ev No | AJ4: Round Title | AK4: Code | AL4: Track | AM4: Country | AN4: Type | AO4: R1 Length | AP4: R2 Length | AQ4: Setup | AR4: Components | AV4: Ev No | AW4: Round Title | AX4: Code | AY4: Track | AZ4: Country | BA4: Type | BB4: R1 Length | BC4: R2 Length | BD4: Setup | BE4: Components | BI4: Code | BJ4: Track | BK4: Country | BL4: Type | BM4: Circuit Length | BN4: Incident Score | BO4: DNF Score | BP4: Tyre Wear | BQ4: Setup | BR4: Components | BV4: Session | BW4: Details | BZ4: Pos | CA4: Q | CB4: R1 | CC4: R2 | CF4: Pos | CG4: R1 | CH4: R2
B5: Bruh Racing | C5: Lola | D5: Chevrolet | E5: Pirelli | G5: Bottas | I5: Lola | J5: Chevrolet | K5: Firestone | N5: P1 | O5: 5 | P5: 15 | Q5: 10 | T5: P1 | U5: 10 | V5: 25 | W5: 15 | Z5: P1 | AA5: 30 | AB5: 20 | AE5: P1 | AF5: 12 | AI5: E1 | AJ5: Brazilian Event | AK5: Interlagos | AL5: =VLOOKUP(AK5, trackList, 2, FALSE) -> Autodromo Jose Carlos Pace | AM5: =VLOOKUP(AK5, trackList, 3, FALSE) -> Brazil | AN5: =VLOOKUP(AK5, trackList, 4, FALSE) -> Road Course | AO5: =CONCATENATE(CEILING(VLOOKUP(AN5, lengthDetails, 2, FALSE) / VLOOKUP(AK5, trackList, 5, FALSE), 1), " Laps") -> 38 Laps | AP5: =CONCATENATE(CEILING(VLOOKUP(AN5, lengthDetails, 3, FALSE) / VLOOKUP(AK5, trackList, 5, FALSE), 1), " Laps") -> 31 Laps | AQ5: =VLOOKUP(AK5, trackList, 9, FALSE) -> Chassis | AR5: =VLOOKUP(AK5, trackList, 10, FALSE) -> Aero | AS5: =VLOOKUP(AK5, trackList, 11, FALSE) -> Engine | AV5: E1 | AW5: Australian Event | AX5: Adelaide | AY5: =VLOOKUP(AX5, trackList, 2, FALSE) -> Adelaide Street Circuit | AZ5: =VLOOKUP(AX5, trackList, 3, FALSE) -> Australia | BA5: =VLOOKUP(AX5, trackList, 4, FALSE) -> Street Course | BB5: =CONCATENATE(CEILING(VLOOKUP(BA5, lengthDetails, 2, FALSE) / VLOOKUP(AX5, trackList, 5, FALSE), 1), " Laps") -> 40 Laps | BC5: =CONCATENATE(CEILING(VLOOKUP(BA5, lengthDetails, 3, FALSE) / VLOOKUP(AX5, trackList, 5, FALSE), 1), " Laps") -> 34 Laps | BD5: =VLOOKUP(AX5, trackList, 9, FALSE) -> Suspension | BE5: =VLOOKUP(AX5, trackList, 10, FALSE) -> Chassis | BF5: =VLOOKUP(AX5, trackList, 11, FALSE) -> Suspension | BI5: Adelaide | BJ5: Adelaide Street Circuit | BK5: Australia | BL5: Street Course | BM5: 3.78 | BN5: 1 | BO5: 1 | BP5: 2 | BQ5: Suspension | BR5: Chassis | BS5: Suspension | BV5: Practice | BW5: Single Session, provides Small Bonus | BZ5: P1 | CA5: 10 | CB5: 25 | CC5: 15 | CF5: P1 | CG5: 30 | CH5: 20
B6: Tactically Perfect Racing | C6: Tatuus | D6: Porsche | E6: Michelin | G6: Niks | I6: March | J6: Honda | N6: P2 | O6: 4 | P6: 12 | Q6: 8 | T6: P2 | U6: 8 | V6: 18 | W6: 12 | Z6: P2 | AA6: 22 | AB6: 15 | AE6: P2 | AF6: 10 | AI6: E2 | AJ6: American Event | AK6: Indianapolis | AL6: =VLOOKUP(AK6, trackList, 2, FALSE) -> Indianapolis Motor Speedway | AM6: =VLOOKUP(AK6, trackList, 3, FALSE) -> United States | AN6: =VLOOKUP(AK6, trackList, 4, FALSE) -> Speedway | AO6: =CONCATENATE(CEILING(VLOOKUP(AN6, lengthDetails, 2, FALSE) / VLOOKUP(AK6, trackList, 5, FALSE), 1), " Laps") -> 75 Laps | AP6: =CONCATENATE(CEILING(VLOOKUP(AN6, lengthDetails, 3, FALSE) / VLOOKUP(AK6, trackList, 5, FALSE), 1), " Laps") -> 50 Laps | AQ6: =VLOOKUP(AK6, trackList, 9, FALSE) -> Aero | AR6: =VLOOKUP(AK6, trackList, 10, FALSE) -> Aero | AS6: =VLOOKUP(AK6, trackList, 11, FALSE) -> Engine | AV6: E2 | AW6: Chinese Event | AX6: Shanghai | AY6: =VLOOKUP(AX6, trackList, 2, FALSE) -> Shanghai International Circuit | AZ6: =VLOOKUP(AX6, trackList, 3, FALSE) -> China | BA6: =VLOOKUP(AX6, trackList, 4, FALSE) -> Road Course | BB6: =CONCATENATE(CEILING(VLOOKUP(BA6, lengthDetails, 2, FALSE) / VLOOKUP(AX6, trackList, 5, FALSE), 1), " Laps") -> 30 Laps | BC6: =CONCATENATE(CEILING(VLOOKUP(BA6, lengthDetails, 3, FALSE) / VLOOKUP(AX6, trackList, 5, FALSE), 1), " Laps") -> 24 Laps | BD6: =VLOOKUP(AX6, trackList, 9, FALSE) -> Aero | BE6: =VLOOKUP(AX6, trackList, 10, FALSE) -> Aero | BF6: =VLOOKUP(AX6, trackList, 11, FALSE) -> Engine | BI6: Bahrain | BJ6: Bahrain International Circuit | BK6: Bahrain | BL6: Road Course | BM6: 5.412 | BN6: 4 | BO6: 4 | BP6: 4 | BQ6: Aero | BR6: Aero | BS6: Engine | BV6: Qualifying 1 | BW6: Every Driver gets a Single Lap | BZ6: P2 | CA6: 8 | CB6: 18 | CC6: 12 | CF6: P2 | CG6: 22 | CH6: 15
B7: Super Corby Racing | C7: Tatuus | D7: Porsche | E7: Michelin | G7: Kenzie | I7: Reynard | J7: Porsche | K7: Pirelli | N7: P3 | O7: 3 | P7: 10 | Q7: 6 | T7: P3 | U7: 6 | V7: 15 | W7: 10 | Z7: P3 | AA7: 18 | AB7: 12 | AE7: P3 | AF7: 8 | AI7: E3 | AJ7: Texan Event | AK7: Texas | AL7: =VLOOKUP(AK7, trackList, 2, FALSE) -> Texas Motor Speedway | AM7: =VLOOKUP(AK7, trackList, 3, FALSE) -> United States | AN7: =VLOOKUP(AK7, trackList, 4, FALSE) -> Speedway | AO7: =CONCATENATE(CEILING(VLOOKUP(AN7, lengthDetails, 2, FALSE) / VLOOKUP(AK7, trackList, 5, FALSE), 1), " Laps") -> 125 Laps | AP7: =CONCATENATE(CEILING(VLOOKUP(AN7, lengthDetails, 3, FALSE) / VLOOKUP(AK7, trackList, 5, FALSE), 1), " Laps") -> 83 Laps | AQ7: =VLOOKUP(AK7, trackList, 9, FALSE) -> Aero | AR7: =VLOOKUP(AK7, trackList, 10, FALSE) -> Aero | AS7: =VLOOKUP(AK7, trackList, 11, FALSE) -> Engine | AV7: E3 | AW7: Malaysian Event | AX7: Sepang | AY7: =VLOOKUP(AX7, trackList, 2, FALSE) -> Sepang International Circuit | AZ7: =VLOOKUP(AX7, trackList, 3, FALSE) -> Malaysia | BA7: =VLOOKUP(AX7, trackList, 4, FALSE) -> Road Course | BB7: =CONCATENATE(CEILING(VLOOKUP(BA7, lengthDetails, 2, FALSE) / VLOOKUP(AX7, trackList, 5, FALSE), 1), " Laps") -> 29 Laps | BC7: =CONCATENATE(CEILING(VLOOKUP(BA7, lengthDetails, 3, FALSE) / VLOOKUP(AX7, trackList, 5, FALSE), 1), " Laps") -> 24 Laps | BD7: =VLOOKUP(AX7, trackList, 9, FALSE) -> Aero | BE7: =VLOOKUP(AX7, trackList, 10, FALSE) -> Chassis | BF7: =VLOOKUP(AX7, trackList, 11, FALSE) -> Engine | BI7: Jerez | BJ7: Circuito de Jerez Angel Nieto | BK7: Spain | BL7: Road Course | BM7: 4.428 | BN7: 2 | BO7: 3 | BP7: 3 | BQ7: Chassis | BR7: Chassis | BS7: Suspension | BV7: Qualifying 2 | BW7: Top 8 run in Reverse Order to Set Grid | BZ7: P3 | CA7: 6 | CB7: 15 | CC7: 10 | CF7: P3 | CG7: 18 | CH7: 12
B8: Blue Flag Racing | C8: Reynard | D8: Honda | E8: Firestone | G8: Kenzie | I8: Tatuus | J8: Toyota | K8: Michelin | N8: P4 | O8: 2 | P8: 8 | Q8: 5 | T8: P4 | U8: 5 | V8: 12 | W8: 9 | Z8: P4 | AA8: 15 | AB8: 10 | AE8: P4 | AF8: 7 | AI8: E4 | AJ8: South African Event | AK8: Kyalami | AL8: =VLOOKUP(AK8, trackList, 2, FALSE) -> Kyalami Grand Prix Circuit | AM8: =VLOOKUP(AK8, trackList, 3, FALSE) -> South Africa | AN8: =VLOOKUP(AK8, trackList, 4, FALSE) -> Road Course | AO8: =CONCATENATE(CEILING(VLOOKUP(AN8, lengthDetails, 2, FALSE) / VLOOKUP(AK8, trackList, 5, FALSE), 1), " Laps") -> 36 Laps | AP8: =CONCATENATE(CEILING(VLOOKUP(AN8, lengthDetails, 3, FALSE) / VLOOKUP(AK8, trackList, 5, FALSE), 1), " Laps") -> 29 Laps | AQ8: =VLOOKUP(AK8, trackList, 9, FALSE) -> Suspension | AR8: =VLOOKUP(AK8, trackList, 10, FALSE) -> Chassis | AS8: =VLOOKUP(AK8, trackList, 11, FALSE) -> Suspension | AV8: E4 | AW8: Singapore Event | AX8: Singapore | AY8: =VLOOKUP(AX8, trackList, 2, FALSE) -> Marina Bay Street Circuit | AZ8: =VLOOKUP(AX8, trackList, 3, FALSE) -> Singapore | BA8: =VLOOKUP(AX8, trackList, 4, FALSE) -> Street Course | BB8: =CONCATENATE(CEILING(VLOOKUP(BA8, lengthDetails, 2, FALSE) / VLOOKUP(AX8, trackList, 5, FALSE), 1), " Laps") -> 31 Laps | BC8: =CONCATENATE(CEILING(VLOOKUP(BA8, lengthDetails, 3, FALSE) / VLOOKUP(AX8, trackList, 5, FALSE), 1), " Laps") -> 26 Laps | BD8: =VLOOKUP(AX8, trackList, 9, FALSE) -> Suspension | BE8: =VLOOKUP(AX8, trackList, 10, FALSE) -> Aero | BF8: =VLOOKUP(AX8, trackList, 11, FALSE) -> Engine | BI8: Mugello | BJ8: Autodromo Nazionale del Mugello | BK8: Italy | BL8: Road Course | BM8: 5.245 | BN8: 4 | BO8: 4 | BP8: 4 | BQ8: Aero | BR8: Aero | BS8: Engine | BV8: Race 1 | BW8: Uses Results of Q2 to form Grid, Most Points | BZ8: P4 | CA8: 5 | CB8: 12 | CC8: 9 | CF8: P4 | CG8: 15 | CH8: 10
B9: 98-99 Racing | C9: March | D9: Porsche | E9: Pirelli | G9: Niks | N9: P5 | O9: 1 | P9: 6 | Q9: 4 | T9: P5 | U9: 4 | V9: 10 | W9: 8 | Z9: P5 | AA9: 12 | AB9: 8 | AE9: P5 | AF9: 6 | AI9: E5 | AJ9: Spanish Event | AK9: Jerez | AL9: =VLOOKUP(AK9, trackList, 2, FALSE) -> Circuito de Jerez Angel Nieto | AM9: =VLOOKUP(AK9, trackList, 3, FALSE) -> Spain | AN9: =VLOOKUP(AK9, trackList, 4, FALSE) -> Road Course | AO9: =CONCATENATE(CEILING(VLOOKUP(AN9, lengthDetails, 2, FALSE) / VLOOKUP(AK9, trackList, 5, FALSE), 1), " Laps") -> 37 Laps | AP9: =CONCATENATE(CEILING(VLOOKUP(AN9, lengthDetails, 3, FALSE) / VLOOKUP(AK9, trackList, 5, FALSE), 1), " Laps") -> 30 Laps | AQ9: =VLOOKUP(AK9, trackList, 9, FALSE) -> Chassis | AR9: =VLOOKUP(AK9, trackList, 10, FALSE) -> Chassis | AS9: =VLOOKUP(AK9, trackList, 11, FALSE) -> Suspension | AV9: E5 | AW9: Japanese Event | AX9: Suzuka | AY9: =VLOOKUP(AX9, trackList, 2, FALSE) -> Suzuka Circuit | AZ9: =VLOOKUP(AX9, trackList, 3, FALSE) -> Japan | BA9: =VLOOKUP(AX9, trackList, 4, FALSE) -> Road Course | BB9: =CONCATENATE(CEILING(VLOOKUP(BA9, lengthDetails, 2, FALSE) / VLOOKUP(AX9, trackList, 5, FALSE), 1), " Laps") -> 28 Laps | BC9: =CONCATENATE(CEILING(VLOOKUP(BA9, lengthDetails, 3, FALSE) / VLOOKUP(AX9, trackList, 5, FALSE), 1), " Laps") -> 23 Laps | BD9: =VLOOKUP(AX9, trackList, 9, FALSE) -> Chassis | BE9: =VLOOKUP(AX9, trackList, 10, FALSE) -> Aero | BF9: =VLOOKUP(AX9, trackList, 11, FALSE) -> Chassis | BI9: Silverstone | BJ9: Silverstone Circuit | BK9: United Kingdom | BL9: Road Course | BM9: 5.891 | BN9: 5 | BO9: 4 | BP9: 4 | BQ9: Aero | BR9: Aero | BS9: Engine | BV9: Race 2 | BW9: Uses Results of Q1 to form Grid, Less Points | BZ9: P5 | CA9: 4 | CB9: 10 | CC9: 8 | CF9: P5 | CG9: 12 | CH9: 8
B10: Project D Racing | C10: Reynard | D10: Toyota | E10: Michelin | G10: Beasty | N10: P6 | P10: 5 | Q10: 3 | T10: P6 | U10: 3 | V10: 8 | W10: 7 | Z10: P6 | AA10: 10 | AB10: 7 | AE10: P6 | AF10: 5 | AI10: E6 | AJ10: French Event | AK10: Magny-Cours | AL10: =VLOOKUP(AK10, trackList, 2, FALSE) -> Circuit de Magny-Cours Nevers | AM10: =VLOOKUP(AK10, trackList, 3, FALSE) -> France | AN10: =VLOOKUP(AK10, trackList, 4, FALSE) -> Road Course | AO10: =CONCATENATE(CEILING(VLOOKUP(AN10, lengthDetails, 2, FALSE) / VLOOKUP(AK10, trackList, 5, FALSE), 1), " Laps") -> 37 Laps | AP10: =CONCATENATE(CEILING(VLOOKUP(AN10, lengthDetails, 3, FALSE) / VLOOKUP(AK10, trackList, 5, FALSE), 1), " Laps") -> 30 Laps | AQ10: =VLOOKUP(AK10, trackList, 9, FALSE) -> Suspension | AR10: =VLOOKUP(AK10, trackList, 10, FALSE) -> Chassis | AS10: =VLOOKUP(AK10, trackList, 11, FALSE) -> Suspension | AV10: E6 | AW10: Motegi Event | AX10: Motegi Oval | AY10: =VLOOKUP(AX10, trackList, 2, FALSE) -> Twin Ring Motegi Oval | AZ10: =VLOOKUP(AX10, trackList, 3, FALSE) -> Japan | BA10: =VLOOKUP(AX10, trackList, 4, FALSE) -> Speedway | BB10: =CONCATENATE(CEILING(VLOOKUP(BA10, lengthDetails, 2, FALSE) / VLOOKUP(AX10, trackList, 5, FALSE), 1), " Laps") -> 121 Laps | BC10: =CONCATENATE(CEILING(VLOOKUP(BA10, lengthDetails, 3, FALSE) / VLOOKUP(AX10, trackList, 5, FALSE), 1), " Laps") -> 81 Laps | BD10: =VLOOKUP(AX10, trackList, 9, FALSE) -> Aero | BE10: =VLOOKUP(AX10, trackList, 10, FALSE) -> Aero | BF10: =VLOOKUP(AX10, trackList, 11, FALSE) -> Engine | BI10: Magny-Cours | BJ10: Circuit de Magny-Cours Nevers | BK10: France | BL10: Road Course | BM10: 4.411 | BN10: 2 | BO10: 3 | BP10: 3 | BQ10: Suspension | BR10: Chassis | BS10: Suspension | BZ10: P6 | CA10: 3 | CB10: 8 | CC10: 7 | CF10: P6 | CG10: 10 | CH10: 7
B11: Team Stellar | C11: March | D11: Honda | E11: Firestone | G11: Kevin | K11: Pirelli | N11: P7 | P11: 4 | Q11: 2 | T11: P7 | U11: 2 | V11: 6 | W11: 6 | Z11: P7 | AA11: 9 | AB11: 6 | AE11: P7 | AF11: 4 | AI11: E7 | AJ11: Monaco Event | AK11: Monaco | AL11: =VLOOKUP(AK11, trackList, 2, FALSE) -> Circuit de Monaco | AM11: =VLOOKUP(AK11, trackList, 3, FALSE) -> Monaco | AN11: =VLOOKUP(AK11, trackList, 4, FALSE) -> Street Course | AO11: =CONCATENATE(CEILING(VLOOKUP(AN11, lengthDetails, 2, FALSE) / VLOOKUP(AK11, trackList, 5, FALSE), 1), " Laps") -> 45 Laps | AP11: =CONCATENATE(CEILING(VLOOKUP(AN11, lengthDetails, 3, FALSE) / VLOOKUP(AK11, trackList, 5, FALSE), 1), " Laps") -> 38 Laps | AQ11: =VLOOKUP(AK11, trackList, 9, FALSE) -> Chassis | AR11: =VLOOKUP(AK11, trackList, 10, FALSE) -> Aero | AS11: =VLOOKUP(AK11, trackList, 11, FALSE) -> Chassis | AV11: E7 | AW11: Portuguese Event | AX11: Estoril | AY11: =VLOOKUP(AX11, trackList, 2, FALSE) -> Circuito do Estoril | AZ11: =VLOOKUP(AX11, trackList, 3, FALSE) -> Portugal | BA11: =VLOOKUP(AX11, trackList, 4, FALSE) -> Road Course | BB11: =CONCATENATE(CEILING(VLOOKUP(BA11, lengthDetails, 2, FALSE) / VLOOKUP(AX11, trackList, 5, FALSE), 1), " Laps") -> 39 Laps | BC11: =CONCATENATE(CEILING(VLOOKUP(BA11, lengthDetails, 3, FALSE) / VLOOKUP(AX11, trackList, 5, FALSE), 1), " Laps") -> 32 Laps | BD11: =VLOOKUP(AX11, trackList, 9, FALSE) -> Aero | BE11: =VLOOKUP(AX11, trackList, 10, FALSE) -> Chassis | BF11: =VLOOKUP(AX11, trackList, 11, FALSE) -> Engine | BI11: Nurburgring | BJ11: Nurburgring GP Circuit | BK11: Germany | BL11: Road Course | BM11: 5.148 | BN11: 3 | BO11: 3 | BP11: 3 | BQ11: Chassis | BR11: Aero | BS11: Chassis | BZ11: P7 | CA11: 2 | CB11: 6 | CC11: 6 | CF11: P7 | CG11: 9 | CH11: 6
B12: Sim Party Racing | C12: Lola | D12: Chevrolet | E12: Michelin | G12: Kebab | K12: Hankook | N12: P8 | P12: 3 | Q12: 1 | T12: P8 | U12: 1 | V12: 5 | W12: 5 | Z12: P8 | AA12: 8 | AB12: 5 | AE12: P8 | AF12: 3 | AI12: E8 | AJ12: German Event | AK12: Nurburgring | AL12: =VLOOKUP(AK12, trackList, 2, FALSE) -> Nurburgring GP Circuit | AM12: =VLOOKUP(AK12, trackList, 3, FALSE) -> Germany | AN12: =VLOOKUP(AK12, trackList, 4, FALSE) -> Road Course | AO12: =CONCATENATE(CEILING(VLOOKUP(AN12, lengthDetails, 2, FALSE) / VLOOKUP(AK12, trackList, 5, FALSE), 1), " Laps") -> 32 Laps | AP12: =CONCATENATE(CEILING(VLOOKUP(AN12, lengthDetails, 3, FALSE) / VLOOKUP(AK12, trackList, 5, FALSE), 1), " Laps") -> 26 Laps | AQ12: =VLOOKUP(AK12, trackList, 9, FALSE) -> Chassis | AR12: =VLOOKUP(AK12, trackList, 10, FALSE) -> Aero | AS12: =VLOOKUP(AK12, trackList, 11, FALSE) -> Chassis | AV12: E8 | AW12: Spanish Event | AX12: Jerez | AY12: =VLOOKUP(AX12, trackList, 2, FALSE) -> Circuito de Jerez Angel Nieto | AZ12: =VLOOKUP(AX12, trackList, 3, FALSE) -> Spain | BA12: =VLOOKUP(AX12, trackList, 4, FALSE) -> Road Course | BB12: =CONCATENATE(CEILING(VLOOKUP(BA12, lengthDetails, 2, FALSE) / VLOOKUP(AX12, trackList, 5, FALSE), 1), " Laps") -> 37 Laps | BC12: =CONCATENATE(CEILING(VLOOKUP(BA12, lengthDetails, 3, FALSE) / VLOOKUP(AX12, trackList, 5, FALSE), 1), " Laps") -> 30 Laps | BD12: =VLOOKUP(AX12, trackList, 9, FALSE) -> Chassis | BE12: =VLOOKUP(AX12, trackList, 10, FALSE) -> Chassis | BF12: =VLOOKUP(AX12, trackList, 11, FALSE) -> Suspension | BI12: Kyalami | BJ12: Kyalami Grand Prix Circuit | BK12: South Africa | BL12: Road Course | BM12: 4.529 | BN12: 2 | BO12: 4 | BP12: 4 | BQ12: Suspension | BR12: Chassis | BS12: Suspension | BV12: Junior Series Round Format | BZ12: P8 | CA12: 1 | CB12: 5 | CC12: 5 | CF12: P8 | CG12: 8 | CH12: 5
B13: Centurion Engineering | C13: Lola | D13: Porsche | E13: Michelin | G13: hopeless | N13: P9 | P13: 2 | T13: P9 | V13: 4 | W13: 4 | Z13: P9 | AA13: 7 | AB13: 4 | AE13: P9 | AF13: 2 | AI13: E9 | AJ13: British Event | AK13: Silverstone | AL13: =VLOOKUP(AK13, trackList, 2, FALSE) -> Silverstone Circuit | AM13: =VLOOKUP(AK13, trackList, 3, FALSE) -> United Kingdom | AN13: =VLOOKUP(AK13, trackList, 4, FALSE) -> Road Course | AO13: =CONCATENATE(CEILING(VLOOKUP(AN13, lengthDetails, 2, FALSE) / VLOOKUP(AK13, trackList, 5, FALSE), 1), " Laps") -> 28 Laps | AP13: =CONCATENATE(CEILING(VLOOKUP(AN13, lengthDetails, 3, FALSE) / VLOOKUP(AK13, trackList, 5, FALSE), 1), " Laps") -> 23 Laps | AQ13: =VLOOKUP(AK13, trackList, 9, FALSE) -> Aero | AR13: =VLOOKUP(AK13, trackList, 10, FALSE) -> Aero | AS13: =VLOOKUP(AK13, trackList, 11, FALSE) -> Engine | AV13: E9 | AW13: French Event | AX13: Magny-Cours | AY13: =VLOOKUP(AX13, trackList, 2, FALSE) -> Circuit de Magny-Cours Nevers | AZ13: =VLOOKUP(AX13, trackList, 3, FALSE) -> France | BA13: =VLOOKUP(AX13, trackList, 4, FALSE) -> Road Course | BB13: =CONCATENATE(CEILING(VLOOKUP(BA13, lengthDetails, 2, FALSE) / VLOOKUP(AX13, trackList, 5, FALSE), 1), " Laps") -> 37 Laps | BC13: =CONCATENATE(CEILING(VLOOKUP(BA13, lengthDetails, 3, FALSE) / VLOOKUP(AX13, trackList, 5, FALSE), 1), " Laps") -> 30 Laps | BD13: =VLOOKUP(AX13, trackList, 9, FALSE) -> Suspension | BE13: =VLOOKUP(AX13, trackList, 10, FALSE) -> Chassis | BF13: =VLOOKUP(AX13, trackList, 11, FALSE) -> Suspension | BI13: Interlagos | BJ13: Autodromo Jose Carlos Pace | BK13: Brazil | BL13: Road Course | BM13: 4.309 | BN13: 4 | BO13: 3 | BP13: 3 | BQ13: Chassis | BR13: Aero | BS13: Engine | BZ13: P9 | CA13: 0 | CB13: 4 | CC13: 4 | CF13: P9 | CG13: 7 | CH13: 4
B14: APR GP Racing | C14: Tatuus | D14: Toyota | E14: Firestone | G14: Brandon | N14: P10 | P14: 1 | T14: P10 | V14: 3 | W14: 3 | Z14: P10 | AA14: 6 | AB14: 3 | AE14: P10 | AF14: 1 | AI14: E10 | AJ14: Italian Event | AK14: Imola | AL14: =VLOOKUP(AK14, trackList, 2, FALSE) -> Imola Circuit | AM14: =VLOOKUP(AK14, trackList, 3, FALSE) -> Italy | AN14: =VLOOKUP(AK14, trackList, 4, FALSE) -> Road Course | AO14: =CONCATENATE(CEILING(VLOOKUP(AN14, lengthDetails, 2, FALSE) / VLOOKUP(AK14, trackList, 5, FALSE), 1), " Laps") -> 33 Laps | AP14: =CONCATENATE(CEILING(VLOOKUP(AN14, lengthDetails, 3, FALSE) / VLOOKUP(AK14, trackList, 5, FALSE), 1), " Laps") -> 27 Laps | AQ14: =VLOOKUP(AK14, trackList, 9, FALSE) -> Chassis | AR14: =VLOOKUP(AK14, trackList, 10, FALSE) -> Chassis | AS14: =VLOOKUP(AK14, trackList, 11, FALSE) -> Suspension | AV14: E10 | AW14: German Event | AX14: Nurburgring | AY14: =VLOOKUP(AX14, trackList, 2, FALSE) -> Nurburgring GP Circuit | AZ14: =VLOOKUP(AX14, trackList, 3, FALSE) -> Germany | BA14: =VLOOKUP(AX14, trackList, 4, FALSE) -> Road Course | BB14: =CONCATENATE(CEILING(VLOOKUP(BA14, lengthDetails, 2, FALSE) / VLOOKUP(AX14, trackList, 5, FALSE), 1), " Laps") -> 32 Laps | BC14: =CONCATENATE(CEILING(VLOOKUP(BA14, lengthDetails, 3, FALSE) / VLOOKUP(AX14, trackList, 5, FALSE), 1), " Laps") -> 26 Laps | BD14: =VLOOKUP(AX14, trackList, 9, FALSE) -> Chassis | BE14: =VLOOKUP(AX14, trackList, 10, FALSE) -> Aero | BF14: =VLOOKUP(AX14, trackList, 11, FALSE) -> Chassis | BI14: Daytona RC | BJ14: Daytona International Speedway RC | BK14: United States | BL14: Road Course | BM14: 5.729 | BN14: 5 | BO14: 2 | BP14: 2 | BQ14: Aero | BR14: Aero | BS14: Engine | BV14: Session | BW14: Details | BZ14: P10 | CA14: 0 | CB14: 3 | CC14: 3 | CF14: P10 | CG14: 6 | CH14: 3
N15: Pole | P15: 1 | T15: P11 | V15: 2 | W15: 2 | Z15: P11 | AA15: 5 | AB15: 2 | AE15: Pole | AF15: 3 | AI15: E11 | AJ15: Turkish Event | AK15: Istanbul | AL15: =VLOOKUP(AK15, trackList, 2, FALSE) -> Istanbul Park | AM15: =VLOOKUP(AK15, trackList, 3, FALSE) -> Turkiye | AN15: =VLOOKUP(AK15, trackList, 4, FALSE) -> Road Course | AO15: =CONCATENATE(CEILING(VLOOKUP(AN15, lengthDetails, 2, FALSE) / VLOOKUP(AK15, trackList, 5, FALSE), 1), " Laps") -> 30 Laps | AP15: =CONCATENATE(CEILING(VLOOKUP(AN15, lengthDetails, 3, FALSE) / VLOOKUP(AK15, trackList, 5, FALSE), 1), " Laps") -> 25 Laps | AQ15: =VLOOKUP(AK15, trackList, 9, FALSE) -> Aero | AR15: =VLOOKUP(AK15, trackList, 10, FALSE) -> Aero | AS15: =VLOOKUP(AK15, trackList, 11, FALSE) -> Engine | AV15: E11 | AW15: Italian Event | AX15: Mugello | AY15: =VLOOKUP(AX15, trackList, 2, FALSE) -> Autodromo Nazionale del Mugello | AZ15: =VLOOKUP(AX15, trackList, 3, FALSE) -> Italy | BA15: =VLOOKUP(AX15, trackList, 4, FALSE) -> Road Course | BB15: =CONCATENATE(CEILING(VLOOKUP(BA15, lengthDetails, 2, FALSE) / VLOOKUP(AX15, trackList, 5, FALSE), 1), " Laps") -> 31 Laps | BC15: =CONCATENATE(CEILING(VLOOKUP(BA15, lengthDetails, 3, FALSE) / VLOOKUP(AX15, trackList, 5, FALSE), 1), " Laps") -> 25 Laps | BD15: =VLOOKUP(AX15, trackList, 9, FALSE) -> Aero | BE15: =VLOOKUP(AX15, trackList, 10, FALSE) -> Aero | BF15: =VLOOKUP(AX15, trackList, 11, FALSE) -> Engine | BI15: Daytona | BJ15: Daytona International Speedway | BK15: United States | BL15: Speedway | BM15: 4.023 | BN15: 5 | BO15: 2 | BP15: 2 | BQ15: Aero | BR15: Aero | BS15: Engine | BV15: Practice | BW15: Single Session, provides Small Bonus | BZ15: P11 | CA15: 0 | CB15: 2 | CC15: 2 | CF15: P11 | CG15: 5 | CH15: 2
T16: P12 | V16: 1 | W16: 1 | Z16: P12 | AA16: 4 | AB16: 1 | AI16: E12 | AJ16: Japanese Event | AK16: Motegi Oval | AL16: =VLOOKUP(AK16, trackList, 2, FALSE) -> Twin Ring Motegi Oval | AM16: =VLOOKUP(AK16, trackList, 3, FALSE) -> Japan | AN16: =VLOOKUP(AK16, trackList, 4, FALSE) -> Speedway | AO16: =CONCATENATE(CEILING(VLOOKUP(AN16, lengthDetails, 2, FALSE) / VLOOKUP(AK16, trackList, 5, FALSE), 1), " Laps") -> 121 Laps | AP16: =CONCATENATE(CEILING(VLOOKUP(AN16, lengthDetails, 3, FALSE) / VLOOKUP(AK16, trackList, 5, FALSE), 1), " Laps") -> 81 Laps | AQ16: =VLOOKUP(AK16, trackList, 9, FALSE) -> Aero | AR16: =VLOOKUP(AK16, trackList, 10, FALSE) -> Aero | AS16: =VLOOKUP(AK16, trackList, 11, FALSE) -> Engine | AV16: E12 | AW16: Belgian Event | AX16: Spa | AY16: =VLOOKUP(AX16, trackList, 2, FALSE) -> Circuit de Spa-Francorshamps | AZ16: =VLOOKUP(AX16, trackList, 3, FALSE) -> Belgium | BA16: =VLOOKUP(AX16, trackList, 4, FALSE) -> Road Course | BB16: =CONCATENATE(CEILING(VLOOKUP(BA16, lengthDetails, 2, FALSE) / VLOOKUP(AX16, trackList, 5, FALSE), 1), " Laps") -> 23 Laps | BC16: =CONCATENATE(CEILING(VLOOKUP(BA16, lengthDetails, 3, FALSE) / VLOOKUP(AX16, trackList, 5, FALSE), 1), " Laps") -> 19 Laps | BD16: =VLOOKUP(AX16, trackList, 9, FALSE) -> Aero | BE16: =VLOOKUP(AX16, trackList, 10, FALSE) -> Aero | BF16: =VLOOKUP(AX16, trackList, 11, FALSE) -> Engine | BI16: Sepang | BJ16: Sepang International Circuit | BK16: Malaysia | BL16: Road Course | BM16: 5.543 | BN16: 4 | BO16: 4 | BP16: 4 | BQ16: Aero | BR16: Chassis | BS16: Engine | BV16: Qualifying | BW16: Every Driver gets a Single Lap, no Points | BZ16: P12 | CA16: 0 | CB16: 1 | CC16: 1 | CF16: P12 | CG16: 4 | CH16: 1
B17: Hunter Motorsport | C17: March | D17: Honda | E17: Firestone | T17: Pole | W17: 1 | Z17: P13 | AA17: 3 | AI17: E13 | AJ17: Singapore Event | AK17: Singapore | AL17: =VLOOKUP(AK17, trackList, 2, FALSE) -> Marina Bay Street Circuit | AM17: =VLOOKUP(AK17, trackList, 3, FALSE) -> Singapore | AN17: =VLOOKUP(AK17, trackList, 4, FALSE) -> Street Course | AO17: =CONCATENATE(CEILING(VLOOKUP(AN17, lengthDetails, 2, FALSE) / VLOOKUP(AK17, trackList, 5, FALSE), 1), " Laps") -> 31 Laps | AP17: =CONCATENATE(CEILING(VLOOKUP(AN17, lengthDetails, 3, FALSE) / VLOOKUP(AK17, trackList, 5, FALSE), 1), " Laps") -> 26 Laps | AQ17: =VLOOKUP(AK17, trackList, 9, FALSE) -> Suspension | AR17: =VLOOKUP(AK17, trackList, 10, FALSE) -> Aero | AS17: =VLOOKUP(AK17, trackList, 11, FALSE) -> Engine | AV17: E13 | AW17: European Event | AX17: Barcelona | AY17: =VLOOKUP(AX17, trackList, 2, FALSE) -> Circuit de Barcelona-Catalunya | AZ17: =VLOOKUP(AX17, trackList, 3, FALSE) -> Spain | BA17: =VLOOKUP(AX17, trackList, 4, FALSE) -> Road Course | BB17: =CONCATENATE(CEILING(VLOOKUP(BA17, lengthDetails, 2, FALSE) / VLOOKUP(AX17, trackList, 5, FALSE), 1), " Laps") -> 35 Laps | BC17: =CONCATENATE(CEILING(VLOOKUP(BA17, lengthDetails, 3, FALSE) / VLOOKUP(AX17, trackList, 5, FALSE), 1), " Laps") -> 28 Laps | BD17: =VLOOKUP(AX17, trackList, 9, FALSE) -> Chassis | BE17: =VLOOKUP(AX17, trackList, 10, FALSE) -> Chassis | BF17: =VLOOKUP(AX17, trackList, 11, FALSE) -> Engine | BI17: Spa | BJ17: Circuit de Spa-Francorshamps | BK17: Belgium | BL17: Road Course | BM17: 7.004 | BN17: 4 | BO17: 2 | BP17: 2 | BQ17: Aero | BR17: Aero | BS17: Engine | BV17: Race | BW17: Single Race, no Stops, Main Series R2 Points | BZ17: P13 | CA17: 0 | CB17: 0 | CC17: 0 | CF17: P13 | CG17: 3 | CH17: 0
B18: URT Motorsports | C18: March | D18: Toyota | E18: Pirelli | Z18: P14 | AA18: 2 | AI18: E14 | AJ18: Australian Event | AK18: Adelaide | AL18: =VLOOKUP(AK18, trackList, 2, FALSE) -> Adelaide Street Circuit | AM18: =VLOOKUP(AK18, trackList, 3, FALSE) -> Australia | AN18: =VLOOKUP(AK18, trackList, 4, FALSE) -> Street Course | AO18: =CONCATENATE(CEILING(VLOOKUP(AN18, lengthDetails, 2, FALSE) / VLOOKUP(AK18, trackList, 5, FALSE), 1), " Laps") -> 40 Laps | AP18: =CONCATENATE(CEILING(VLOOKUP(AN18, lengthDetails, 3, FALSE) / VLOOKUP(AK18, trackList, 5, FALSE), 1), " Laps") -> 34 Laps | AQ18: =VLOOKUP(AK18, trackList, 9, FALSE) -> Suspension | AR18: =VLOOKUP(AK18, trackList, 10, FALSE) -> Chassis | AS18: =VLOOKUP(AK18, trackList, 11, FALSE) -> Suspension | AV18: E14 | AW18: British Event | AX18: Silverstone | AY18: =VLOOKUP(AX18, trackList, 2, FALSE) -> Silverstone Circuit | AZ18: =VLOOKUP(AX18, trackList, 3, FALSE) -> United Kingdom | BA18: =VLOOKUP(AX18, trackList, 4, FALSE) -> Road Course | BB18: =CONCATENATE(CEILING(VLOOKUP(BA18, lengthDetails, 2, FALSE) / VLOOKUP(AX18, trackList, 5, FALSE), 1), " Laps") -> 28 Laps | BC18: =CONCATENATE(CEILING(VLOOKUP(BA18, lengthDetails, 3, FALSE) / VLOOKUP(AX18, trackList, 5, FALSE), 1), " Laps") -> 23 Laps | BD18: =VLOOKUP(AX18, trackList, 9, FALSE) -> Aero | BE18: =VLOOKUP(AX18, trackList, 10, FALSE) -> Aero | BF18: =VLOOKUP(AX18, trackList, 11, FALSE) -> Engine | BI18: Monza | BJ18: Autodromo Nazionale di Monza | BK18: Italy | BL18: Road Course | BM18: 5.793 | BN18: 4 | BO18: 2 | BP18: 2 | BQ18: Aero | BR18: Aero | BS18: Engine | BZ18: P14 | CA18: 0 | CB18: 0 | CC18: 0 | CF18: P14 | CG18: 2 | CH18: 0
Z19: P15 | AA19: 1 | AV19: E15 | AW19: Turkish Event | AX19: Istanbul | AY19: =VLOOKUP(AX19, trackList, 2, FALSE) -> Istanbul Park | AZ19: =VLOOKUP(AX19, trackList, 3, FALSE) -> Turkiye | BA19: =VLOOKUP(AX19, trackList, 4, FALSE) -> Road Course | BB19: =CONCATENATE(CEILING(VLOOKUP(BA19, lengthDetails, 2, FALSE) / VLOOKUP(AX19, trackList, 5, FALSE), 1), " Laps") -> 30 Laps | BC19: =CONCATENATE(CEILING(VLOOKUP(BA19, lengthDetails, 3, FALSE) / VLOOKUP(AX19, trackList, 5, FALSE), 1), " Laps") -> 25 Laps | BD19: =VLOOKUP(AX19, trackList, 9, FALSE) -> Aero | BE19: =VLOOKUP(AX19, trackList, 10, FALSE) -> Aero | BF19: =VLOOKUP(AX19, trackList, 11, FALSE) -> Engine | BI19: Hockenheim | BJ19: Hockenheimring | BK19: Germany | BL19: Road Course | BM19: 4.574 | BN19: 4 | BO19: 3 | BP19: 3 | BQ19: Chassis | BR19: Aero | BS19: Chassis | BZ19: P15 | CA19: 0 | CB19: 0 | CC19: 0 | CF19: P15 | CG19: 1 | CH19: 0
T20: Main Series Points System | Z20: Pole | AA20: 3 | AB20: 1 | AV20: E16 | AW20: Brazilian Event | AX20: Interlagos | AY20: =VLOOKUP(AX20, trackList, 2, FALSE) -> Autodromo Jose Carlos Pace | AZ20: =VLOOKUP(AX20, trackList, 3, FALSE) -> Brazil | BA20: =VLOOKUP(AX20, trackList, 4, FALSE) -> Road Course | BB20: =CONCATENATE(CEILING(VLOOKUP(BA20, lengthDetails, 2, FALSE) / VLOOKUP(AX20, trackList, 5, FALSE), 1), " Laps") -> 38 Laps | BC20: =CONCATENATE(CEILING(VLOOKUP(BA20, lengthDetails, 3, FALSE) / VLOOKUP(AX20, trackList, 5, FALSE), 1), " Laps") -> 31 Laps | BD20: =VLOOKUP(AX20, trackList, 9, FALSE) -> Chassis | BE20: =VLOOKUP(AX20, trackList, 10, FALSE) -> Aero | BF20: =VLOOKUP(AX20, trackList, 11, FALSE) -> Engine | BI20: CoTA | BJ20: Circuit of The Americas | BK20: United States | BL20: Road Course | BM20: 5.513 | BN20: 3 | BO20: 3 | BP20: 3 | BQ20: Chassis | BR20: Aero | BS20: Engine | BZ20: P16 | CA20: 0 | CB20: 0 | CC20: 0 | CF20: P16 | CG20: 0 | CH20: 0
AN21: Road Course | AO21: 160 | AP21: 130 | AV21: E17 | AW21: Mexican Event | AX21: Mexico City | AY21: =VLOOKUP(AX21, trackList, 2, FALSE) -> Autodromo Hermanos Rodriguez | AZ21: =VLOOKUP(AX21, trackList, 3, FALSE) -> Mexico | BA21: =VLOOKUP(AX21, trackList, 4, FALSE) -> Road Course | BB21: =CONCATENATE(CEILING(VLOOKUP(BA21, lengthDetails, 2, FALSE) / VLOOKUP(AX21, trackList, 5, FALSE), 1), " Laps") -> 38 Laps | BC21: =CONCATENATE(CEILING(VLOOKUP(BA21, lengthDetails, 3, FALSE) / VLOOKUP(AX21, trackList, 5, FALSE), 1), " Laps") -> 31 Laps | BD21: =VLOOKUP(AX21, trackList, 9, FALSE) -> Aero | BE21: =VLOOKUP(AX21, trackList, 10, FALSE) -> Aero | BF21: =VLOOKUP(AX21, trackList, 11, FALSE) -> Engine | BI21: Suzuka | BJ21: Suzuka Circuit | BK21: Japan | BL21: Road Course | BM21: 5.807 | BN21: 2 | BO21: 3 | BP21: 3 | BQ21: Chassis | BR21: Aero | BS21: Chassis | BV21: Aero | BZ21: P17 | CA21: 0 | CB21: 0 | CC21: 0 | CF21: P17 | CG21: 0 | CH21: 0
T22: Pos | U22: Q | V22: R1 | W22: R2 | AN22: Street Course | AO22: 150 | AP22: 125 | AV22: E18 | AW22: American Event | AX22: Long Beach | AY22: =VLOOKUP(AX22, trackList, 2, FALSE) -> Streets of Long Beach | AZ22: =VLOOKUP(AX22, trackList, 3, FALSE) -> United States | BA22: =VLOOKUP(AX22, trackList, 4, FALSE) -> Street Course | BB22: =CONCATENATE(CEILING(VLOOKUP(BA22, lengthDetails, 2, FALSE) / VLOOKUP(AX22, trackList, 5, FALSE), 1), " Laps") -> 48 Laps | BC22: =CONCATENATE(CEILING(VLOOKUP(BA22, lengthDetails, 3, FALSE) / VLOOKUP(AX22, trackList, 5, FALSE), 1), " Laps") -> 40 Laps | BD22: =VLOOKUP(AX22, trackList, 9, FALSE) -> Chassis | BE22: =VLOOKUP(AX22, trackList, 10, FALSE) -> Aero | BF22: =VLOOKUP(AX22, trackList, 11, FALSE) -> Chassis | BI22: Fuji | BJ22: Fuji Speedway | BK22: Japan | BL22: Road Course | BM22: 4.563 | BN22: 3 | BO22: 4 | BP22: 2 | BQ22: Aero | BR22: Aero | BS22: Engine | BV22: Chassis | BZ22: P18 | CA22: 0 | CB22: 0 | CC22: 0 | CF22: P18 | CG22: 0 | CH22: 0
T23: P1 | U23: 10 | V23: 25 | W23: 15 | AN23: Short Oval | AO23: 300 | AP23: 200 | AV23: E19 | AW23: Indianapolis Event | AX23: Indianapolis | AY23: =VLOOKUP(AX23, trackList, 2, FALSE) -> Indianapolis Motor Speedway | AZ23: =VLOOKUP(AX23, trackList, 3, FALSE) -> United States | BA23: =VLOOKUP(AX23, trackList, 4, FALSE) -> Speedway | BB23: =CONCATENATE(CEILING(VLOOKUP(BA23, lengthDetails, 2, FALSE) / VLOOKUP(AX23, trackList, 5, FALSE), 1), " Laps") -> 75 Laps | BC23: =CONCATENATE(CEILING(VLOOKUP(BA23, lengthDetails, 3, FALSE) / VLOOKUP(AX23, trackList, 5, FALSE), 1), " Laps") -> 50 Laps | BD23: =VLOOKUP(AX23, trackList, 9, FALSE) -> Aero | BE23: =VLOOKUP(AX23, trackList, 10, FALSE) -> Aero | BF23: =VLOOKUP(AX23, trackList, 11, FALSE) -> Engine | BI23: Barcelona | BJ23: Circuit de Barcelona-Catalunya | BK23: Spain | BL23: Road Course | BM23: 4.657 | BN23: 3 | BO23: 3 | BP23: 4 | BQ23: Chassis | BR23: Chassis | BS23: Engine | BV23: Susp | BZ23: P19 | CA23: 0 | CB23: 0 | CC23: 0 | CF23: P19 | CG23: 0 | CH23: 0
T24: P2 | U24: 8 | V24: 18 | W24: 12 | AN24: Speedway | AO24: 300 | AP24: 200 | AV24: E20 | AW24: TDS13 Finale | AX24: Daytona | AY24: =VLOOKUP(AX24, trackList, 2, FALSE) -> Daytona International Speedway | AZ24: =VLOOKUP(AX24, trackList, 3, FALSE) -> United States | BA24: =VLOOKUP(AX24, trackList, 4, FALSE) -> Speedway | BB24: =CONCATENATE(CEILING(VLOOKUP(BA24, lengthDetails, 2, FALSE) / VLOOKUP(AX24, trackList, 5, FALSE), 1), " Laps") -> 75 Laps | BC24: =CONCATENATE(CEILING(VLOOKUP(BA24, lengthDetails, 3, FALSE) / VLOOKUP(AX24, trackList, 5, FALSE), 1), " Laps") -> 50 Laps | BD24: =VLOOKUP(AX24, trackList, 9, FALSE) -> Aero | BE24: =VLOOKUP(AX24, trackList, 10, FALSE) -> Aero | BF24: =VLOOKUP(AX24, trackList, 11, FALSE) -> Engine | BI24: Istanbul | BJ24: Istanbul Park | BK24: Turkiye | BL24: Road Course | BM24: 5.338 | BN24: 3 | BO24: 3 | BP24: 3 | BQ24: Aero | BR24: Aero | BS24: Engine | BV24: Engine | BZ24: P20 | CA24: 0 | CB24: 0 | CC24: 0 | CF24: P20 | CG24: 0 | CH24: 0
T25: P3 | U25: 6 | V25: 15 | W25: 10 | BI25: Singapore | BJ25: Marina Bay Street Circuit | BK25: Singapore | BL25: Street Course | BM25: 4.927 | BN25: 1 | BO25: 2 | BP25: 2 | BQ25: Suspension | BR25: Aero | BS25: Engine | BZ25: P21 | CA25: 0 | CB25: 0 | CC25: 0 | CF25: P21 | CG25: 0 | CH25: 0
T26: P4 | U26: 5 | V26: 12 | W26: 8 | AO26: =4.023 * 95 -> 382.185 | BI26: Dubai | BJ26: Dubai Autodrome | BK26: UAE | BL26: Road Course | BM26: 5.39 | BN26: 5 | BO26: 4 | BP26: 3 | BQ26: Chassis | BR26: Chassis | BS26: Engine | BZ26: P22 | CA26: 0 | CB26: 0 | CC26: 0 | CF26: P22 | CG26: 0 | CH26: 0
T27: P5 | U27: 4 | V27: 10 | W27: 6 | BI27: Monaco | BJ27: Circuit de Monaco | BK27: Monaco | BL27: Street Course | BM27: 3.37 | BN27: 1 | BO27: 1 | BP27: 1 | BQ27: Chassis | BR27: Aero | BS27: Chassis | BZ27: P23 | CA27: 0 | CB27: 0 | CC27: 0 | CF27: P23 | CG27: 0 | CH27: 0
T28: P6 | U28: 3 | V28: 8 | W28: 5 | AN28: Road Course | AO28: 200 | AP28: 165 | BI28: Long Beach | BJ28: Streets of Long Beach | BK28: United States | BL28: Street Course | BM28: 3.167 | BN28: 1 | BO28: 1 | BP28: 1 | BQ28: Chassis | BR28: Aero | BS28: Chassis | BZ28: P24 | CA28: 0 | CB28: 0 | CC28: 0 | CF28: P24 | CG28: 0 | CH28: 0
B29: He has no idea what he is doing Junior Series | T29: P7 | U29: 2 | V29: 6 | W29: 4 | AN29: Street Course | AO29: 195 | AP29: 160 | BI29: Imola | BJ29: Imola Circuit | BK29: Italy | BL29: Road Course | BM29: 4.909 | BN29: 2 | BO29: 2 | BP29: 3 | BQ29: Chassis | BR29: Chassis | BS29: Suspension | BZ29: P25 | CA29: 0 | CB29: 0 | CC29: 0 | CF29: P25 | CG29: 0 | CH29: 0
T30: P8 | U30: 1 | V30: 5 | W30: 3 | AN30: Short Oval | AO30: 300 | AP30: 215 | BI30: Phoenix | BJ30: Phoenix Raceway | BK30: United States | BL30: Short Oval | BM30: 2.414 | BN30: 1 | BO30: 1 | BP30: 1 | BQ30: Suspension | BR30: Aero | BS30: Engine | BZ30: P26 | CA30: 0 | CB30: 0 | CC30: 0 | CF30: P26 | CG30: 0 | CH30: 0
B31: Team Name | C31: Chassis | D31: Engine | E31: Tyres | T31: P9 | V31: 4 | W31: 2 | AN31: Speedway | AO31: 300 | AP31: 215 | BI31: Gateway | BJ31: WorldWide Technology Raceway | BK31: United States | BL31: Short Oval | BM31: 2.012 | BN31: 1 | BO31: 1 | BP31: 1 | BQ31: Aero | BR31: Aero | BS31: Chassis | BZ31: P27 | CA31: 0 | CB31: 0 | CC31: 0 | CF31: P27 | CG31: 0 | CH31: 0
B32: Junior Series Team 1 | C32: Dallara | E32: Michelin | T32: P10 | V32: 3 | W32: 1 | BI32: Texas | BJ32: Texas Motor Speedway | BK32: United States | BL32: Speedway | BM32: 2.414 | BN32: 1 | BO32: 1 | BP32: 1 | BQ32: Aero | BR32: Aero | BS32: Engine | BZ32: P28 | CA32: 0 | CB32: 0 | CC32: 0 | CF32: P28 | CG32: 0 | CH32: 0
B33: Junior Series Team 2 | C33: Dallara | E33: Michelin | T33: P11 | V33: 2 | BI33: Arlington | BJ33: Streets of Arlington | BK33: United States | BL33: Street Course | BM33: 4.368 | BN33: 1 | BO33: 1 | BP33: 3 | BQ33: Suspension | BR33: Aero | BS33: Engine | BZ33: P29 | CA33: 0 | CB33: 0 | CC33: 0 | CF33: P29 | CG33: 0 | CH33: 0
B34: Junior Series Team 3 | C34: Dallara | E34: Michelin | T34: P12 | V34: 1 | BI34: Indianapolis | BJ34: Indianapolis Motor Speedway | BK34: United States | BL34: Speedway | BM34: 4.023 | BN34: 1 | BO34: 1 | BP34: 1 | BQ34: Aero | BR34: Aero | BS34: Engine | BZ34: P30 | CA34: 0 | CB34: 0 | CC34: 0 | CF34: P30 | CG34: 0 | CH34: 0
B35: Junior Series Team 4 | C35: Dallara | E35: Michelin | BI35: IMS Road | BJ35: Indianapolis Motor Speedway RC | BK35: United States | BL35: Road Course | BM35: 3.923 | BN35: 3 | BO35: 2 | BP35: 2 | BQ35: Suspension | BR35: Aero | BS35: Engine | BZ35: P- | CA35: 0 | CB35: 0 | CC35: 0 | CF35: P- | CG35: 0 | CH35: 0
B36: Junior Series Team 5 | C36: Dallara | E36: Michelin | BI36: Shanghai | BJ36: Shanghai International Circuit | BK36: China | BL36: Road Course | BM36: 5.451 | BN36: 4 | BO36: 3 | BP36: 2 | BQ36: Aero | BR36: Aero | BS36: Engine | BZ36: PWDN | CA36: 0 | CB36: 0 | CC36: 0 | CF36: PWDN | CG36: 0 | CH36: 0
B37: Junior Series Team 6 | C37: Dallara | E37: Michelin | T37: Main Series Points System | BI37: Motegi RC | BJ37: Twin Ring Motegi Road Course | BK37: Japan | BL37: Road Course | BM37: 4.801 | BQ37: Chassis | BR37: Aero | BS37: Engine | BZ37: PDNF | CA37: 0 | CB37: 0 | CC37: 0 | CF37: PDNF | CG37: 0 | CH37: 0
B38: Junior Series Team 7 | C38: Dallara | E38: Michelin | BI38: Motegi Oval | BJ38: Twin Ring Motegi Oval | BK38: Japan | BL38: Speedway | BM38: 2.493 | BQ38: Aero | BR38: Aero | BS38: Engine | BZ38: PNC | CA38: 0 | CB38: 0 | CC38: 0 | CF38: PNC | CG38: 0 | CH38: 0
B39: Junior Series Team 8 | C39: Dallara | E39: Michelin | T39: Pos | U39: Q | V39: R1 | W39: R2 | BI39: Portimao | BJ39: Algarve International Circuit | BK39: Portugal | BL39: Road Course | BM39: 4.653 | BQ39: Aero | BR39: Aero | BS39: Engine | BZ39: PDNS | CA39: 0 | CB39: 0 | CC39: 0 | CF39: PDNS | CG39: 0 | CH39: 0
B40: Junior Series Team 9 | C40: Dallara | E40: Michelin | T40: P1 | U40: 10 | V40: 25 | W40: 15 | BI40: Estoril | BJ40: Circuito do Estoril | BK40: Portugal | BL40: Road Course | BM40: 4.182 | BQ40: Aero | BR40: Chassis | BS40: Engine | BZ40: PDSQ | CA40: 0 | CB40: 0 | CC40: 0 | CF40: PDSQ | CG40: 0 | CH40: 0
B41: Junior Series Team 10 | C41: Dallara | E41: Michelin | T41: P2 | U41: 8 | V41: 18 | W41: 12 | BI41: Mexico City | BJ41: Autodromo Hermanos Rodriguez | BK41: Mexico | BL41: Road Course | BM41: 4.304 | BQ41: Aero | BR41: Aero | BS41: Engine | BZ41: PEXC | CA41: 0 | CB41: 0 | CC41: 0 | CF41: PEXC | CG41: 0 | CH41: 0
...

Sheet Lineups
B2: TDS12
B3: Team Lineups
B4: Driver Name | C4: Car No | D4: Team Name | E4: Spine | F4: Engine | G4: Tyres
B5: Kimi Antonelli | C5: #4 | D5: =IF(Start!B8 <> "", Start!B8, "") -> Blue Flag Racing | E5: =IF(Start!C8 <> "", Start!C8, "") -> Reynard | F5: =IF(Start!D8 <> "", Start!D8, "") -> Honda | G5: =IF(Start!E8 <> "", Start!E8, "") -> Firestone | J5: #4 | M5: #4
B6: Arvid Lindblad | C6: #20 | J6: #20
B7: Dino Beganovic | C7: #69 | J7: #69
B8: Isack Hadjar | C8: RES | J8: RES
B9: Jamie Chadwick | C9: #18 | D9: =IF(Start!B11 <> "", Start!B11, "") -> Team Stellar | E9: =IF(Start!C11 <> "", Start!C11, "") -> March | F9: =IF(Start!D11 <> "", Start!D11, "") -> Honda | G9: =IF(Start!E11 <> "", Start!E11, "") -> Firestone | J9: #18
B10: Chloe Chambers | C10: #14 | J10: #14
B11: Aurelia Nobels | C11: #22 | J11: #22
B12: Maya Weug | C12: RES | J12: RES
B13: Victor Martins | C13: #30 | D13: =IF(Start!B14 <> "", Start!B14, "") -> APR GP Racing | E13: =IF(Start!C14 <> "", Start!C14, "") -> Tatuus | F13: =IF(Start!D14 <> "", Start!D14, "") -> Toyota | G13: =IF(Start!E14 <> "", Start!E14, "") -> Firestone | J13: #30
B14: Doriane Pin | C14: #28 | J14: #28
B15: Dan Ticktum | C15: #29 | J15: #29
B16: Ugo Ugochukwu | C16: RES | J16: RES
B17: Lando Norris | C17: #24 | D17: =IF(Start!B7 <> "", Start!B7, "") -> Super Corby Racing | E17: =IF(Start!C7 <> "", Start!C7, "") -> Tatuus | F17: =IF(Start!D7 <> "", Start!D7, "") -> Porsche | G17: =IF(Start!E7 <> "", Start!E7, "") -> Michelin | J17: #24
B18: David Malukas | C18: #5 | J18: #5
B19: Oscar Piastri | C19: #27 | J19: #27
B20: Pato O'Ward | C20: #25 | J20: #25
B21: Alex Dunne | C21: RES | J21: RES
B22: Christian Lundgaard | C22: #8 | D22: =IF(Start!B5 <> "", Start!B5, "") -> Bruh Racing | E22: =IF(Start!C5 <> "", Start!C5, "") -> Lola | F22: =IF(Start!D5 <> "", Start!D5, "") -> Chevrolet | G22: =IF(Start!E5 <> "", Start!E5, "") -> Pirelli | J22: #8
B23: Rinus VeeKay | C23: #7 | J23: #7
B24: Tuukka Taponen | C24: #9 | J24: #9
B25: Oliver Goethe | C25: RES | J25: RES
B26: Colton Herta | C26: #101 | D26: =IF(Start!B6 <> "", Start!B6, "") -> Tactically Perfect Racing | E26: =IF(Start!C6 <> "", Start!C6, "") -> Tatuus | F26: =IF(Start!D6 <> "", Start!D6, "") -> Porsche | G26: =IF(Start!E6 <> "", Start!E6, "") -> Michelin | J26: #101
B27: George Russell | C27: #100 | J27: #100
B28: Theo Pourchaire | C28: #102 | J28: #102
B29: Gabriel Bortoleto | C29: RES | J29: RES
B30: Yuki Tsunoda | C30: #97 | D30: =IF(Start!B9 <> "", Start!B9, "") -> 98-99 Racing | E30: =IF(Start!C9 <> "", Start!C9, "") -> March | F30: =IF(Start!D9 <> "", Start!D9, "") -> Porsche | G30: =IF(Start!E9 <> "", Start!E9, "") -> Pirelli | J30: #97
B31: Ayumu Iwasa | C31: #98 | J31: #98
B32: Kyffin Simpson | C32: #99 | J32: #99
B33: Sacha Fenestraz | C33: RES | J33: RES
B34: Kyle Kirkwood | C34: #12 | D34: =IF(Start!B13 <> "", Start!B13, "") -> Centurion Engineering | E34: =IF(Start!C13 <> "", Start!C13, "") -> Lola | F34: =IF(Start!D13 <> "", Start!D13, "") -> Porsche | G34: =IF(Start!E13 <> "", Start!E13, "") -> Michelin | J34: #12
B35: Alex Palou | C35: #10 | J35: #10
B36: Abbi Pulling | C36: #11 | J36: #11
B37: Marta Garcia | C37: RES | J37: RES
B38: Callum Ilott | C38: #90 | D38: =IF(Start!B10 <> "", Start!B10, "") -> Project D Racing | E38: =IF(Start!C10 <> "", Start!C10, "") -> Reynard | F38: =IF(Start!D10 <> "", Start!D10, "") -> Toyota | G38: =IF(Start!E10 <> "", Start!E10, "") -> Michelin | J38: #90
B39: Ritomo Miyata | C39: #92 | J39: #92
B40: Hunter McElrea | C40: #91 | J40: #91
B41: Marcus Armstrong | C41: RES | J41: RES
...

Sheet Drivers
B2: Driver List | H2: Available Drivers
B4: Driver Name | C4: Driver Score | D4: Crash Score | E4: Deg Score | H4: Formula 1 + Formula E | I4: Formula 2 | J4: F3 + F1A | K4: IndyCar | L4: WEC, NXT + Misc | O4: Retiring Drivers | R4: Retiring Drivers | U4: Retiring Drivers | X4: Retiring Drivers
B5: Jack Doohan | C5: 94 | D5: 3 | E5: 4 | H5: Jack Doohan | I5: Leonardo Fornaroli | J5: Noah Stromsted | K5: David Malukas | L5: Mick Schumacher | O5: Scott Dixon | R5: Robert Kubica | U5: Felix Rosenqvist | X5: Pierre Gasly
B6: Franco Colapinto | C6: 96 | D6: 2 | E6: 2 | H6: Franco Colapinto | I6: Roman Stanek | J6: Rafael Camara | K6: Santino Ferrucci | L6: Myles Rowe | O6: Kamui Kobayashi | R6: Marcus Ericsson | U6: Carlos Sainz Jr | X6: Toby Sowery
